{
 "cells": [
  {
   "cell_type": "code",
   "execution_count": 1,
   "id": "1f24e907-25fd-470c-a06e-e5c8d05ae878",
   "metadata": {},
   "outputs": [],
   "source": [
    "from IPython.core.interactiveshell import InteractiveShell\n",
    "InteractiveShell.ast_node_interactivity = \"all\""
   ]
  },
  {
   "cell_type": "markdown",
   "id": "7eb1f93b-575f-4236-a7d6-a011de330509",
   "metadata": {},
   "source": [
    "In Python, all exceptions must be instances of a class that derives from [`BaseException`](https://docs.python.org/3/library/exceptions.html#BaseException). In a [`try`](https://docs.python.org/3/reference/compound_stmts.html#try) statement with an [`except`](https://docs.python.org/3/reference/compound_stmts.html#except) clause that mentions a particular class, that clause also handles any exception classes derived from that class (but not exception classes from which *it* is derived). Two exception classes that are not related via subclassing are never equivalent, even if they have the same name.\n",
    "\n",
    "The built-in exceptions listed below can be generated by the interpreter or built-in functions. Except where mentioned, they have an “associated value” indicating the detailed cause of the error. This may be a string or a tuple of several items of information (e.g., an error code and a string explaining the code). The associated value is usually passed as arguments to the exception class’s constructor.\n",
    "\n",
    "User code can raise built-in exceptions. This can be used to test an exception handler or to report an error condition “just like” the situation in which the interpreter raises the same exception; but beware that there is nothing to prevent user code from raising an inappropriate error.\n",
    "\n",
    "The built-in exception classes can be subclassed to define new exceptions; programmers are encouraged to derive new exceptions from the [`Exception`](https://docs.python.org/3/library/exceptions.html#Exception) class or one of its subclasses, and not from [`BaseException`](https://docs.python.org/3/library/exceptions.html#BaseException). More information on defining exceptions is available in the Python Tutorial under [User-defined Exceptions](https://docs.python.org/3/tutorial/errors.html#tut-userexceptions).\n",
    "\n",
    "> 在Python中，所有的异常必须是派生自 [`BaseException`](https://docs.python.org/3/library/exceptions.html#BaseException) 的类的实例。在带有[`except`](https://docs.python.org/3/reference/compound_stmts.html#except)子句的[`try`](https://docs.python.org/3/reference/compound_stmts.html#try)语句中，如果提到某个特定的类，该子句也会处理从该类派生的任何异常类 (但不包括*它*派生的异常类)。两个没有通过子类关系的异常类永远不会等价，即使它们有相同的名字。\n",
    ">\n",
    "> 下面列出的内置异常可以由解释器或内置函数生成。除了提到的地方，它们有一个 \"关联值\"，表示错误的详细原因。这可能是一个字符串或几个信息项的元组（例如，一个错误代码和一个解释该代码的字符串）。相关值通常作为参数传递给异常类的构造函数。\n",
    ">\n",
    "> 用户代码可以引发内置异常。这可以用来测试一个异常处理程序，或者报告一个错误情况，\"就像 \"解释器引发同样的异常的情况一样；但是要注意，没有什么可以阻止用户代码引发一个不合适的错误。\n",
    ">\n",
    "> 内置的异常类可以被子类化以定义新的异常；我们鼓励程序员从[`Exception`](https://docs.python.org/3/library/exceptions.html#Exception)类或其子类中派生新的异常，而不是从[`BaseException`](https://docs.python.org/3/library/exceptions.html#BaseException)派生。关于定义异常的更多信息可以在Python教程中的 [User-defined Exceptions](https://docs.python.org/3/tutorial/errors.html#tut-userexceptions) 找到。"
   ]
  },
  {
   "cell_type": "markdown",
   "id": "4f9fc757-ed66-400b-b24f-22eea8c1a4dc",
   "metadata": {},
   "source": [
    "## Exception context"
   ]
  },
  {
   "cell_type": "markdown",
   "id": "50caa358-4dde-41c5-b8e3-1776b701f8cb",
   "metadata": {},
   "source": [
    "When raising a new exception while another exception is already being handled, the new exception’s `__context__` attribute is automatically set to the handled exception. An exception may be handled when an [`except`](https://docs.python.org/3/reference/compound_stmts.html#except) or [`finally`](https://docs.python.org/3/reference/compound_stmts.html#finally) clause, or a [`with`](https://docs.python.org/3/reference/compound_stmts.html#with) statement, is used.\n",
    "\n",
    "This implicit exception context can be supplemented with an explicit cause by using `from` with [`raise`](https://docs.python.org/3/reference/simple_stmts.html#raise):\n",
    "\n",
    "> 当引发一个新的异常，而另一个异常已经被处理时，新的异常的`__context__`属性会自动设置为被处理的异常。当使用[`except`](https://docs.python.org/3/reference/compound_stmts.html#except)或[`finally`](https://docs.python.org/3/reference/compound_stmts.html#finally)子句，或[`with`](https://docs.python.org/3/reference/compound_stmts.html#with)语句时，一个异常可能被处理。\n",
    ">\n",
    "> 这个隐含的异常语境可以通过使用`from`与[`raise`](https://docs.python.org/3/reference/simple_stmts.html#raise)来补充一个显式的原因："
   ]
  },
  {
   "cell_type": "raw",
   "id": "84af1ad1-17e3-4f31-8b8f-7e9da55d48bf",
   "metadata": {},
   "source": [
    "raise new_exc from original_exc"
   ]
  },
  {
   "cell_type": "markdown",
   "id": "756b6af0-f16f-4e2b-8a73-b0d300158781",
   "metadata": {},
   "source": [
    "The expression following [`from`](https://docs.python.org/3/reference/simple_stmts.html#raise) must be an exception or `None`. It will be set as `__cause__` on the raised exception. Setting `__cause__` also implicitly sets the `__suppress_context__` attribute to `True`, so that using `raise new_exc from None` effectively replaces the old exception with the new one for display purposes (e.g. converting [`KeyError`](https://docs.python.org/3/library/exceptions.html#KeyError) to [`AttributeError`](https://docs.python.org/3/library/exceptions.html#AttributeError)), while leaving the old exception available in `__context__` for introspection when debugging.\n",
    "\n",
    "The default traceback display code shows these chained exceptions in addition to the traceback for the exception itself. An explicitly chained exception in `__cause__` is always shown when present. An implicitly chained exception in `__context__` is shown only if `__cause__` is [`None`](https://docs.python.org/3/library/constants.html#None) and `__suppress_context__` is false.\n",
    "\n",
    "In either case, the exception itself is always shown after any chained exceptions so that the final line of the traceback always shows the last exception that was raised.\n",
    "\n",
    "> [`from`](https://docs.python.org/3/reference/simple_stmts.html#raise)后面的表达式必须是一个异常或`None`。它将被设置为引发异常的\"\\_\\_cause\\__\"。设置\"\\_\\_cause\\_\\_\"也隐含地将\"\\_\\_suppress_context\\_\\_\"属性设置为 `True`，因此使用 `raise new_exc from None` 可以有效地将旧的异常替换为新的异常，以便显示（例如将 [`KeyError`](https://docs.python.org/3/library/exceptions.html#KeyError) 转换为 [`AttributeError`](https://docs.python.org/3/library/exceptions.html#AttributeError) ），同时在\"\\_\\_context__\"中保留旧异常以便调试时可以反思。\n",
    ">\n",
    "> 默认的回溯显示代码除了显示异常本身的回溯外，还显示这些连锁的异常。在 `__cause__`中明确的连锁异常在出现时总是被显示。只有在`__cause__`是[`None`](https://docs.python.org/3/library/constants.html#None)并且`__suppress_context__`是假的情况下，才会显示`__context__`中隐含的链式异常。\n",
    ">\n",
    "> 在这两种情况下，异常本身总是显示在任何连锁异常之后，因此回溯的最后一行总是显示最后引发的异常。"
   ]
  },
  {
   "cell_type": "markdown",
   "id": "0d5b52fb-0c98-485c-8aa3-a84a19916762",
   "metadata": {},
   "source": [
    "### Inheriting from built-in exceptions"
   ]
  },
  {
   "cell_type": "markdown",
   "id": "646a6d42-c10c-4c24-a1fa-e772d4261193",
   "metadata": {},
   "source": [
    "User code can create subclasses that inherit from an exception type. It’s recommended to only subclass one exception type at a time to avoid any possible conflicts between how the bases handle the `args` attribute, as well as due to possible memory layout incompatibilities.\n",
    "\n",
    "**CPython implementation detail:** Most built-in exceptions are implemented in C for efficiency, see: [Objects/exceptions.c](https://github.com/python/cpython/tree/3.10/Objects/exceptions.c). Some have custom memory layouts which makes it impossible to create a subclass that inherits from multiple exception types. The memory layout of a type is an implementation detail and might change between Python versions, leading to new conflicts in the future. Therefore, it’s recommended to avoid subclassing multiple exception types altogether.\n",
    "\n",
    "> 用户代码可以创建继承自一个异常类型的子类。我们建议一次只对一个异常类型进行子类化，以避免基类处理`args`属性时可能出现的冲突，以及可能出现的内存布局不兼容的情况。\n",
    ">\n",
    "> **CPython的实现细节：**大多数内置的异常都是用C语言实现的，以提高效率，见[Objects/exceptions.c](https://github.com/python/cpython/tree/3.10/Objects/exceptions.c)。有些有自定义的内存布局，这使得我们不可能创建一个继承自多个异常类型的子类。一个类型的内存布局是一个实现细节，可能会在Python版本之间发生变化，导致未来出现新的冲突。因此，建议完全避免子类化多个异常类型。"
   ]
  },
  {
   "cell_type": "markdown",
   "id": "7565edde-26a8-407f-8602-f6ed4e30866e",
   "metadata": {},
   "source": [
    "## Base classes"
   ]
  },
  {
   "cell_type": "markdown",
   "id": "1e63d0df-06e5-4346-9bec-9a4afff014c1",
   "metadata": {},
   "source": [
    "The following exceptions are used mostly as base classes for other exceptions.\n",
    "\n",
    "> 以下的例外情况主要是作为其他例外情况的基类使用。"
   ]
  },
  {
   "cell_type": "markdown",
   "id": "d354b9bc-9f23-4f8b-a78c-d9c792303520",
   "metadata": {},
   "source": [
    "*exception* `BaseException`\n",
    "\n",
    "The base class for all built-in exceptions. It is not meant to be directly inherited by user-defined classes (for that, use [`Exception`](https://docs.python.org/3/library/exceptions.html#Exception)). If [`str()`](https://docs.python.org/3/library/stdtypes.html#str) is called on an instance of this class, the representation of the argument(s) to the instance are returned, or the empty string when there were no arguments.\n",
    "\n",
    "- `args`\n",
    "\n",
    "  The tuple of arguments given to the exception constructor. Some built-in exceptions (like [`OSError`](https://docs.python.org/3/library/exceptions.html#OSError)) expect a certain number of arguments and assign a special meaning to the elements of this tuple, while others are usually called only with a single string giving an error message.\n",
    "\n",
    "- `with_traceback`(*tb*)\n",
    "\n",
    "  This method sets *tb* as the new traceback for the exception and returns the exception object. It was more commonly used before the exception chaining features of [**PEP 3134**](https://www.python.org/dev/peps/pep-3134) became available. The following example shows how we can convert an instance of `SomeException` into an instance of `OtherException` while preserving the traceback. Once raised, the current frame is pushed onto the traceback of the `OtherException`, as would have happened to the traceback of the original `SomeException` had we allowed it to propagate to the caller.\n",
    "\n",
    "> *exception* `BaseException`.\n",
    ">\n",
    "> 所有内置异常的基类。它并不意味着可以被用户定义的类直接继承（为此，请使用 [`Exception`](https://docs.python.org/3/library/exceptions.html#Exception)）。如果在这个类的实例上调用[`str()`](https://docs.python.org/3/library/stdtypes.html#str)，将返回该实例的参数表示，如果没有参数，则返回空字符串。\n",
    ">\n",
    "> - `args`\n",
    ">\n",
    ">   给予异常构造函数的一串参数。一些内置的异常（如 [`OSError`](https://docs.python.org/3/library/exceptions.html#OSError)）希望有一定数量的参数，并为这个元组的元素赋予特殊的含义，而其他的异常通常只用一个字符串来调用，给出错误信息。\n",
    ">\n",
    "> - `with_traceback`(*tb*)\n",
    ">\n",
    ">   这个方法将*tb*设置为异常的新回溯，并返回异常对象。在[**PEP 3134**](https://www.python.org/dev/peps/pep-3134)的异常链功能出现之前，它是比较常用的。下面的例子展示了我们如何将一个`SomeException`的实例转换成`OtherException`的实例，同时保留回溯。一旦发生，当前帧就会被推到`OtherException`的回溯上，如果我们允许它传播给调用者，那么原始`SomeException`的回溯就会发生。"
   ]
  },
  {
   "cell_type": "code",
   "execution_count": 3,
   "id": "02ec8305-d25a-4356-9c26-35e0ae6b9b96",
   "metadata": {},
   "outputs": [
    {
     "data": {
      "text/plain": [
       "Ellipsis"
      ]
     },
     "execution_count": 3,
     "metadata": {},
     "output_type": "execute_result"
    }
   ],
   "source": [
    "try:\n",
    "    ...\n",
    "except SomeException:\n",
    "    tb = sys.exc_info()[2]\n",
    "    raise OtherException(...).with_traceback(tb)"
   ]
  },
  {
   "cell_type": "markdown",
   "id": "14898b9e-4887-4b2b-9fca-3f084debee07",
   "metadata": {},
   "source": [
    "*exception* `Exception`\n",
    "\n",
    "All built-in, non-system-exiting exceptions are derived from this class. All user-defined exceptions should also be derived from this class.\n",
    "\n",
    "> *exception* `Exception `\n",
    ">\n",
    "> 所有内置的、非系统退出的异常都派生自这个类。所有用户定义的异常也应该派生自这个类。"
   ]
  },
  {
   "cell_type": "markdown",
   "id": "103e8653-5fbb-474e-8c91-04297b5323e1",
   "metadata": {},
   "source": [
    "*exception* `ArithmeticError`\n",
    "\n",
    "The base class for those built-in exceptions that are raised for various arithmetic errors: [`OverflowError`](https://docs.python.org/3/library/exceptions.html#OverflowError), [`ZeroDivisionError`](https://docs.python.org/3/library/exceptions.html#ZeroDivisionError), [`FloatingPointError`](https://docs.python.org/3/library/exceptions.html#FloatingPointError).\n",
    "\n",
    "> *exception* `ArithmeticError`\n",
    ">\n",
    "> 是那些因各种算术错误而引发的内置异常的基类。[`OverflowError`](https://docs.python.org/3/library/exceptions.html#OverflowError), [`ZeroDivisionError`](https://docs.python.org/3/library/exceptions.html#ZeroDivisionError), [`FloatingPointError`](https://docs.python.org/3/library/exceptions.html#FloatingPointError)."
   ]
  },
  {
   "cell_type": "markdown",
   "id": "20a070e2-8374-42b6-b643-c930a93a718b",
   "metadata": {},
   "source": [
    "*exception* `BufferError`\n",
    "\n",
    "Raised when a [buffer](https://docs.python.org/3/c-api/buffer.html#bufferobjects) related operation cannot be performed.\n",
    "\n",
    "> *exception* `BufferError`。\n",
    ">\n",
    "> 当[缓冲区](https://docs.python.org/3/c-api/buffer.html#bufferobjects)相关的操作无法执行时，引发该事件。"
   ]
  },
  {
   "cell_type": "markdown",
   "id": "dfb886be-d77b-4ebd-9db4-ea3f63b95dc8",
   "metadata": {},
   "source": [
    "*exception* `LookupError`\n",
    "\n",
    "The base class for the exceptions that are raised when a key or index used on a mapping or sequence is invalid: [`IndexError`](https://docs.python.org/3/library/exceptions.html#IndexError), [`KeyError`](https://docs.python.org/3/library/exceptions.html#KeyError). This can be raised directly by [`codecs.lookup()`](https://docs.python.org/3/library/codecs.html#codecs.lookup).\n",
    "\n",
    "> *exception* `LookupError`。\n",
    ">\n",
    "> 当映射或序列上使用的键或索引无效时，会引发异常的基类。[`IndexError`](https://docs.python.org/3/library/exceptions.html#IndexError), [`KeyError`](https://docs.python.org/3/library/exceptions.html#KeyError). 这可以由[`codecs.lookup()`](https://docs.python.org/3/library/codecs.html#codecs.lookup)直接引发。"
   ]
  },
  {
   "cell_type": "markdown",
   "id": "1ea2f0c3-bf8b-42c4-83ac-93392b50c44e",
   "metadata": {},
   "source": [
    "## Concrete exceptions"
   ]
  },
  {
   "cell_type": "markdown",
   "id": "81c1b57e-0473-4b18-8880-08bdf34a181a",
   "metadata": {},
   "source": [
    "The following exceptions are the exceptions that are usually raised.\n",
    "\n",
    "> 以下是通常会出现的例外情况。"
   ]
  },
  {
   "cell_type": "markdown",
   "id": "06dad473-86b4-45b8-a057-c29c5cddcb61",
   "metadata": {},
   "source": [
    "Raised when an [`assert`](https://docs.python.org/3/reference/simple_stmts.html#assert) statement fails.\n",
    "\n",
    "> *exception* `AssertionError`\n",
    ">\n",
    "> 当[`assert`](https://docs.python.org/3/reference/simple_stmts.html#assert) 语句失败时引发。"
   ]
  },
  {
   "cell_type": "markdown",
   "id": "2b5aa2a1-2533-411a-846d-0f58967feafb",
   "metadata": {},
   "source": [
    "*exception* `AttributeError`\n",
    "\n",
    "Raised when an attribute reference (see [Attribute references](https://docs.python.org/3/reference/expressions.html#attribute-references)) or assignment fails. (When an object does not support attribute references or attribute assignments at all, [`TypeError`](https://docs.python.org/3/library/exceptions.html#TypeError) is raised.)\n",
    "\n",
    "The `name` and `obj` attributes can be set using keyword-only arguments to the constructor. When set they represent the name of the attribute that was attempted to be accessed and the object that was accessed for said attribute, respectively.\n",
    "\n",
    "*Changed in version 3.10:* Added the `name` and `obj` attributes.\n",
    "\n",
    "> *exception* `AttributeError`。\n",
    ">\n",
    "> 当属性引用（见 [Attribute references](https://docs.python.org/3/reference/expressions.html#attribute-references)）或赋值失败时引发。(当一个对象完全不支持属性引用或属性赋值时，会引发[`TypeError`](https://docs.python.org/3/library/exceptions.html#TypeError)。)\n",
    ">\n",
    "> `name`和`obj`属性可以通过构造函数的纯关键字参数来设置。当设置时，它们分别代表试图被访问的属性的名称和为该属性访问的对象。\n",
    ">\n",
    "> *3.10版中的变化：* 增加了`name`和`obj`属性。"
   ]
  },
  {
   "cell_type": "markdown",
   "id": "43b61b7a-33c1-4664-856c-a20e0b112feb",
   "metadata": {},
   "source": [
    "*exception* `EOFError`\n",
    "\n",
    "Raised when the [`input()`](https://docs.python.org/3/library/functions.html#input) function hits an end-of-file condition (EOF) without reading any data. (N.B.: the `io.IOBase.read()` and [`io.IOBase.readline()`](https://docs.python.org/3/library/io.html#io.IOBase.readline) methods return an empty string when they hit EOF.)\n",
    "\n",
    "> *exception* `EOFError`\n",
    ">\n",
    "> 当[`input()`](https://docs.python.org/3/library/functions.html#input)函数在没有读到任何数据的情况下遇到文件结束条件(EOF)时引发。(注意：`io.IOBase.read()`和[`io.IOBase.readline()`](https://docs.python.org/3/library/io.html#io.IOBase.readline)方法在遇到EOF时返回一个空字符串。)"
   ]
  },
  {
   "cell_type": "markdown",
   "id": "71510448-c2c6-4f1b-a45b-bcbda28a72ea",
   "metadata": {},
   "source": [
    "*exception* `FloatingPointError`\n",
    "\n",
    "Not currently used."
   ]
  },
  {
   "cell_type": "markdown",
   "id": "f5f5a836-d92d-4a51-9af4-7e74fec4878c",
   "metadata": {},
   "source": [
    "*exception* `GeneratorExit`\n",
    "\n",
    "Raised when a [generator](https://docs.python.org/3/glossary.html#term-generator) or [coroutine](https://docs.python.org/3/glossary.html#term-coroutine) is closed; see [`generator.close()`](https://docs.python.org/3/reference/expressions.html#generator.close) and [`coroutine.close()`](https://docs.python.org/3/reference/datamodel.html#coroutine.close). It directly inherits from [`BaseException`](https://docs.python.org/3/library/exceptions.html#BaseException) instead of [`Exception`](https://docs.python.org/3/library/exceptions.html#Exception) since it is technically not an error.\n",
    "\n",
    "> *exception* `GeneratorExit`\n",
    ">\n",
    "> 当[generator](https://docs.python.org/3/glossary.html#term-generator)或[coroutine](https://docs.python.org/3/glossary.html#term-coroutine)被关闭时引发；参见[`generator.close()`](https://docs.python.org/3/reference/expressions.html#generator.close)和[`coroutine.close()`](https://docs.python.org/3/reference/datamodel.html#coroutine.close) 它直接继承了[`BaseException`](https://docs.python.org/3/library/exceptions.html#BaseException)而不是[`Exception`](https://docs.python.org/3/library/exceptions.html#Exception)，因为它在技术上不是一个错误。"
   ]
  },
  {
   "cell_type": "markdown",
   "id": "24b7fef3-d005-44e9-adda-d64d8ebdb176",
   "metadata": {},
   "source": [
    "……"
   ]
  }
 ],
 "metadata": {
  "kernelspec": {
   "display_name": "Python 3 (ipykernel)",
   "language": "python",
   "name": "python3"
  },
  "language_info": {
   "codemirror_mode": {
    "name": "ipython",
    "version": 3
   },
   "file_extension": ".py",
   "mimetype": "text/x-python",
   "name": "python",
   "nbconvert_exporter": "python",
   "pygments_lexer": "ipython3",
   "version": "3.10.4"
  }
 },
 "nbformat": 4,
 "nbformat_minor": 5
}
